[2021-07-21 02:17:17,848] {taskinstance.py:876} INFO - Dependencies all met for <TaskInstance: elasticsearch_dag.print_es_info 2021-07-20T00:00:00+00:00 [queued]>
[2021-07-21 02:17:17,876] {taskinstance.py:876} INFO - Dependencies all met for <TaskInstance: elasticsearch_dag.print_es_info 2021-07-20T00:00:00+00:00 [queued]>
[2021-07-21 02:17:17,877] {taskinstance.py:1067} INFO - 
--------------------------------------------------------------------------------
[2021-07-21 02:17:17,877] {taskinstance.py:1068} INFO - Starting attempt 1 of 1
[2021-07-21 02:17:17,878] {taskinstance.py:1069} INFO - 
--------------------------------------------------------------------------------
[2021-07-21 02:17:17,893] {taskinstance.py:1087} INFO - Executing <Task(PythonOperator): print_es_info> on 2021-07-20T00:00:00+00:00
[2021-07-21 02:17:17,896] {standard_task_runner.py:52} INFO - Started process 3256 to run task
[2021-07-21 02:17:17,908] {standard_task_runner.py:76} INFO - Running: ['airflow', 'tasks', 'run', 'elasticsearch_dag', 'print_es_info', '2021-07-20T00:00:00+00:00', '--job-id', '271', '--pool', 'default_pool', '--raw', '--subdir', 'DAGS_FOLDER/elasticsearch_dag.py', '--cfg-path', '/tmp/tmpcb9kblda', '--error-file', '/tmp/tmpxduasvn1']
[2021-07-21 02:17:17,910] {standard_task_runner.py:77} INFO - Job 271: Subtask print_es_info
[2021-07-21 02:17:17,996] {logging_mixin.py:104} INFO - Running <TaskInstance: elasticsearch_dag.print_es_info 2021-07-20T00:00:00+00:00 [running]> on host airflowvm
[2021-07-21 02:17:18,102] {taskinstance.py:1280} INFO - Exporting the following env vars:
AIRFLOW_CTX_DAG_OWNER=airflow
AIRFLOW_CTX_DAG_ID=elasticsearch_dag
AIRFLOW_CTX_TASK_ID=print_es_info
AIRFLOW_CTX_EXECUTION_DATE=2021-07-20T00:00:00+00:00
AIRFLOW_CTX_DAG_RUN_ID=scheduled__2021-07-20T00:00:00+00:00
[2021-07-21 02:17:18,126] {base.py:69} INFO - Using connection to: id: elasticsearch_default. Host: localhost, Port: 9200, Schema: http, Login: None, Password: None, extra: {}
[2021-07-21 02:17:18,128] {taskinstance.py:1481} ERROR - Task failed with exception
Traceback (most recent call last):
  File "/home/airflow/sandbox/lib/python3.8/site-packages/airflow/models/taskinstance.py", line 1137, in _run_raw_task
    self._prepare_and_execute_task_with_callbacks(context, task)
  File "/home/airflow/sandbox/lib/python3.8/site-packages/airflow/models/taskinstance.py", line 1311, in _prepare_and_execute_task_with_callbacks
    result = self._execute_task(context, task_copy)
  File "/home/airflow/sandbox/lib/python3.8/site-packages/airflow/models/taskinstance.py", line 1341, in _execute_task
    result = task_copy.execute(context=context)
  File "/home/airflow/sandbox/lib/python3.8/site-packages/airflow/operators/python.py", line 150, in execute
    return_value = self.execute_callable()
  File "/home/airflow/sandbox/lib/python3.8/site-packages/airflow/operators/python.py", line 161, in execute_callable
    return self.python_callable(*self.op_args, **self.op_kwargs)
  File "/home/airflow/airflow/dags/elasticsearch_dag.py", line 15, in _print_es_info
    print(hook.info())
AttributeError: 'ElasticHook' object has no attribute 'info'
[2021-07-21 02:17:18,134] {taskinstance.py:1524} INFO - Marking task as FAILED. dag_id=elasticsearch_dag, task_id=print_es_info, execution_date=20210720T000000, start_date=20210721T021717, end_date=20210721T021718
[2021-07-21 02:17:18,196] {local_task_job.py:151} INFO - Task exited with return code 1
