[2021-07-21 04:56:03,825] {taskinstance.py:876} INFO - Dependencies all met for <TaskInstance: elasticsearch_dag.connections_to_es 2021-07-21T04:56:01.310143+00:00 [queued]>
[2021-07-21 04:56:03,853] {taskinstance.py:876} INFO - Dependencies all met for <TaskInstance: elasticsearch_dag.connections_to_es 2021-07-21T04:56:01.310143+00:00 [queued]>
[2021-07-21 04:56:03,854] {taskinstance.py:1067} INFO - 
--------------------------------------------------------------------------------
[2021-07-21 04:56:03,855] {taskinstance.py:1068} INFO - Starting attempt 1 of 1
[2021-07-21 04:56:03,855] {taskinstance.py:1069} INFO - 
--------------------------------------------------------------------------------
[2021-07-21 04:56:03,870] {taskinstance.py:1087} INFO - Executing <Task(PostgresToElasticOperator): connections_to_es> on 2021-07-21T04:56:01.310143+00:00
[2021-07-21 04:56:03,873] {standard_task_runner.py:52} INFO - Started process 7369 to run task
[2021-07-21 04:56:03,887] {standard_task_runner.py:76} INFO - Running: ['airflow', 'tasks', 'run', 'elasticsearch_dag', 'connections_to_es', '2021-07-21T04:56:01.310143+00:00', '--job-id', '280', '--pool', 'default_pool', '--raw', '--subdir', 'DAGS_FOLDER/elasticsearch_dag.py', '--cfg-path', '/tmp/tmpob1acin8', '--error-file', '/tmp/tmpeu5t18m_']
[2021-07-21 04:56:03,888] {standard_task_runner.py:77} INFO - Job 280: Subtask connections_to_es
[2021-07-21 04:56:04,001] {logging_mixin.py:104} INFO - Running <TaskInstance: elasticsearch_dag.connections_to_es 2021-07-21T04:56:01.310143+00:00 [running]> on host airflowvm
[2021-07-21 04:56:04,124] {taskinstance.py:1280} INFO - Exporting the following env vars:
AIRFLOW_CTX_DAG_OWNER=airflow
AIRFLOW_CTX_DAG_ID=elasticsearch_dag
AIRFLOW_CTX_TASK_ID=connections_to_es
AIRFLOW_CTX_EXECUTION_DATE=2021-07-21T04:56:01.310143+00:00
AIRFLOW_CTX_DAG_RUN_ID=manual__2021-07-21T04:56:01.310143+00:00
[2021-07-21 04:56:04,149] {base.py:69} INFO - Using connection to: id: elasticsearch_default. Host: localhost, Port: 9200, Schema: http, Login: None, Password: None, extra: {}
[2021-07-21 04:56:04,183] {base.py:69} INFO - Using connection to: id: ***_default. Host: localhost, Port: 5432, Schema: , Login: ***, Password: ***, extra: {'cursor': 'realdictcursor'}
[2021-07-21 04:56:04,207] {taskinstance.py:1481} ERROR - Task failed with exception
Traceback (most recent call last):
  File "/home/airflow/sandbox/lib/python3.8/site-packages/airflow/models/taskinstance.py", line 1137, in _run_raw_task
    self._prepare_and_execute_task_with_callbacks(context, task)
  File "/home/airflow/sandbox/lib/python3.8/site-packages/airflow/models/taskinstance.py", line 1311, in _prepare_and_execute_task_with_callbacks
    result = self._execute_task(context, task_copy)
  File "/home/airflow/sandbox/lib/python3.8/site-packages/airflow/models/taskinstance.py", line 1341, in _execute_task
    result = task_copy.execute(context=context)
  File "/home/airflow/airflow/plugins/elasticsearch_plugin/operators/postgres_to_elastic.py", line 31, in execute
    with closing(conn_cursor()) as cur: #cur is something to interact with postgres
NameError: name 'conn_cursor' is not defined
[2021-07-21 04:56:04,210] {taskinstance.py:1524} INFO - Marking task as FAILED. dag_id=elasticsearch_dag, task_id=connections_to_es, execution_date=20210721T045601, start_date=20210721T045603, end_date=20210721T045604
[2021-07-21 04:56:04,299] {local_task_job.py:151} INFO - Task exited with return code 1
