[2021-07-21 04:56:19,621] {taskinstance.py:876} INFO - Dependencies all met for <TaskInstance: elasticsearch_dag.connections_to_es 2021-07-21T04:56:16.492952+00:00 [queued]>
[2021-07-21 04:56:19,660] {taskinstance.py:876} INFO - Dependencies all met for <TaskInstance: elasticsearch_dag.connections_to_es 2021-07-21T04:56:16.492952+00:00 [queued]>
[2021-07-21 04:56:19,662] {taskinstance.py:1067} INFO - 
--------------------------------------------------------------------------------
[2021-07-21 04:56:19,663] {taskinstance.py:1068} INFO - Starting attempt 1 of 1
[2021-07-21 04:56:19,664] {taskinstance.py:1069} INFO - 
--------------------------------------------------------------------------------
[2021-07-21 04:56:19,684] {taskinstance.py:1087} INFO - Executing <Task(PostgresToElasticOperator): connections_to_es> on 2021-07-21T04:56:16.492952+00:00
[2021-07-21 04:56:19,688] {standard_task_runner.py:52} INFO - Started process 7463 to run task
[2021-07-21 04:56:19,700] {standard_task_runner.py:76} INFO - Running: ['airflow', 'tasks', 'run', 'elasticsearch_dag', 'connections_to_es', '2021-07-21T04:56:16.492952+00:00', '--job-id', '283', '--pool', 'default_pool', '--raw', '--subdir', 'DAGS_FOLDER/elasticsearch_dag.py', '--cfg-path', '/tmp/tmpgorh3nv6', '--error-file', '/tmp/tmp1bxpbnf8']
[2021-07-21 04:56:19,703] {standard_task_runner.py:77} INFO - Job 283: Subtask connections_to_es
[2021-07-21 04:56:19,825] {logging_mixin.py:104} INFO - Running <TaskInstance: elasticsearch_dag.connections_to_es 2021-07-21T04:56:16.492952+00:00 [running]> on host airflowvm
[2021-07-21 04:56:19,965] {taskinstance.py:1280} INFO - Exporting the following env vars:
AIRFLOW_CTX_DAG_OWNER=airflow
AIRFLOW_CTX_DAG_ID=elasticsearch_dag
AIRFLOW_CTX_TASK_ID=connections_to_es
AIRFLOW_CTX_EXECUTION_DATE=2021-07-21T04:56:16.492952+00:00
AIRFLOW_CTX_DAG_RUN_ID=manual__2021-07-21T04:56:16.492952+00:00
[2021-07-21 04:56:19,985] {base.py:69} INFO - Using connection to: id: elasticsearch_default. Host: localhost, Port: 9200, Schema: http, Login: None, Password: None, extra: {}
[2021-07-21 04:56:20,005] {base.py:69} INFO - Using connection to: id: ***_default. Host: localhost, Port: 5432, Schema: , Login: ***, Password: ***, extra: {'cursor': 'realdictcursor'}
[2021-07-21 04:56:20,021] {taskinstance.py:1481} ERROR - Task failed with exception
Traceback (most recent call last):
  File "/home/airflow/sandbox/lib/python3.8/site-packages/airflow/models/taskinstance.py", line 1137, in _run_raw_task
    self._prepare_and_execute_task_with_callbacks(context, task)
  File "/home/airflow/sandbox/lib/python3.8/site-packages/airflow/models/taskinstance.py", line 1311, in _prepare_and_execute_task_with_callbacks
    result = self._execute_task(context, task_copy)
  File "/home/airflow/sandbox/lib/python3.8/site-packages/airflow/models/taskinstance.py", line 1341, in _execute_task
    result = task_copy.execute(context=context)
  File "/home/airflow/airflow/plugins/elasticsearch_plugin/operators/postgres_to_elastic.py", line 31, in execute
    with closing(conn_cursor()) as cur: #cur is something to interact with postgres
NameError: name 'conn_cursor' is not defined
[2021-07-21 04:56:20,024] {taskinstance.py:1524} INFO - Marking task as FAILED. dag_id=elasticsearch_dag, task_id=connections_to_es, execution_date=20210721T045616, start_date=20210721T045619, end_date=20210721T045620
[2021-07-21 04:56:20,116] {local_task_job.py:151} INFO - Task exited with return code 1
