[2021-07-20 04:37:38,602] {taskinstance.py:876} INFO - Dependencies all met for <TaskInstance: xcom_dag.task_4 2021-07-20T04:37:30.625939+00:00 [queued]>
[2021-07-20 04:37:38,633] {taskinstance.py:876} INFO - Dependencies all met for <TaskInstance: xcom_dag.task_4 2021-07-20T04:37:30.625939+00:00 [queued]>
[2021-07-20 04:37:38,634] {taskinstance.py:1067} INFO - 
--------------------------------------------------------------------------------
[2021-07-20 04:37:38,634] {taskinstance.py:1068} INFO - Starting attempt 1 of 1
[2021-07-20 04:37:38,634] {taskinstance.py:1069} INFO - 
--------------------------------------------------------------------------------
[2021-07-20 04:37:38,648] {taskinstance.py:1087} INFO - Executing <Task(PythonOperator): task_4> on 2021-07-20T04:37:30.625939+00:00
[2021-07-20 04:37:38,651] {standard_task_runner.py:52} INFO - Started process 3911 to run task
[2021-07-20 04:37:38,661] {standard_task_runner.py:76} INFO - Running: ['airflow', 'tasks', 'run', 'xcom_dag', 'task_4', '2021-07-20T04:37:30.625939+00:00', '--job-id', '174', '--pool', 'default_pool', '--raw', '--subdir', 'DAGS_FOLDER/xcom_dag.py', '--cfg-path', '/tmp/tmpl2sety4_', '--error-file', '/tmp/tmpaqu4vz3f']
[2021-07-20 04:37:38,668] {standard_task_runner.py:77} INFO - Job 174: Subtask task_4
[2021-07-20 04:37:38,753] {logging_mixin.py:104} INFO - Running <TaskInstance: xcom_dag.task_4 2021-07-20T04:37:30.625939+00:00 [running]> on host airflowvm
[2021-07-20 04:37:38,868] {taskinstance.py:1280} INFO - Exporting the following env vars:
AIRFLOW_CTX_DAG_OWNER=airflow
AIRFLOW_CTX_DAG_ID=xcom_dag
AIRFLOW_CTX_TASK_ID=task_4
AIRFLOW_CTX_EXECUTION_DATE=2021-07-20T04:37:30.625939+00:00
AIRFLOW_CTX_DAG_RUN_ID=manual__2021-07-20T04:37:30.625939+00:00
[2021-07-20 04:37:38,869] {logging_mixin.py:104} INFO - choose best model
[2021-07-20 04:37:38,870] {taskinstance.py:1481} ERROR - Task failed with exception
Traceback (most recent call last):
  File "/home/airflow/sandbox/lib/python3.8/site-packages/airflow/models/taskinstance.py", line 1137, in _run_raw_task
    self._prepare_and_execute_task_with_callbacks(context, task)
  File "/home/airflow/sandbox/lib/python3.8/site-packages/airflow/models/taskinstance.py", line 1311, in _prepare_and_execute_task_with_callbacks
    result = self._execute_task(context, task_copy)
  File "/home/airflow/sandbox/lib/python3.8/site-packages/airflow/models/taskinstance.py", line 1341, in _execute_task
    result = task_copy.execute(context=context)
  File "/home/airflow/sandbox/lib/python3.8/site-packages/airflow/operators/python.py", line 150, in execute
    return_value = self.execute_callable()
  File "/home/airflow/sandbox/lib/python3.8/site-packages/airflow/operators/python.py", line 161, in execute_callable
    return self.python_callable(*self.op_args, **self.op_kwargs)
  File "/home/airflow/airflow/dags/xcom_dag.py", line 28, in _choose_best_model
    accuracies = ti.xcom_pull(key='model_accuracy',taks_ids =['proceesing_tasks.training_model_a',
  File "/home/airflow/sandbox/lib/python3.8/site-packages/airflow/utils/session.py", line 70, in wrapper
    return func(*args, session=session, **kwargs)
TypeError: xcom_pull() got an unexpected keyword argument 'taks_ids'
[2021-07-20 04:37:38,878] {taskinstance.py:1524} INFO - Marking task as FAILED. dag_id=xcom_dag, task_id=task_4, execution_date=20210720T043730, start_date=20210720T043738, end_date=20210720T043738
[2021-07-20 04:37:38,955] {local_task_job.py:151} INFO - Task exited with return code 1
